2019-06-19 17:29:37,575 [INFO]  Found 1 metrics for ns_id:de4e6d80-ba80-4101-a94f-24d7196f5f2b/vnf_member_index:1
2019-06-19 17:29:37,575 [INFO]  Using <class 'predictors.predictor_utils.Arima'> for prediction
2019-06-19 17:29:37,791 [INFO]  Found 2 metrics for ns_id:de4e6d80-ba80-4101-a94f-24d7196f5f2b/vnf_member_index:1
2019-06-19 17:29:37,791 [INFO]  Using <class 'predictors.predictor_utils.Arima'> for prediction
2019-06-19 17:29:38,003 [INFO]  Found 3 metrics for ns_id:de4e6d80-ba80-4101-a94f-24d7196f5f2b/vnf_member_index:1
2019-06-19 17:29:38,003 [INFO]  Using <class 'predictors.predictor_utils.Arima'> for prediction
2019-06-19 17:29:38,213 [INFO]  Found 4 metrics for ns_id:de4e6d80-ba80-4101-a94f-24d7196f5f2b/vnf_member_index:1
2019-06-19 17:29:38,213 [INFO]  Using <class 'predictors.predictor_utils.Arima'> for prediction
2019-06-19 17:29:38,428 [INFO]  Found 5 metrics for ns_id:de4e6d80-ba80-4101-a94f-24d7196f5f2b/vnf_member_index:1
2019-06-19 17:29:38,428 [INFO]  Using <class 'predictors.predictor_utils.Arima'> for prediction
2019-06-19 17:29:38,640 [INFO]  Found 6 metrics for ns_id:de4e6d80-ba80-4101-a94f-24d7196f5f2b/vnf_member_index:1
2019-06-19 17:29:38,640 [INFO]  Using <class 'predictors.predictor_utils.Arima'> for prediction
2019-06-19 17:29:38,858 [INFO]  Found 7 metrics for ns_id:de4e6d80-ba80-4101-a94f-24d7196f5f2b/vnf_member_index:1
2019-06-19 17:29:38,858 [INFO]  Using <class 'predictors.predictor_utils.Arima'> for prediction
2019-06-19 17:29:39,081 [INFO]  Found 8 metrics for ns_id:de4e6d80-ba80-4101-a94f-24d7196f5f2b/vnf_member_index:1
2019-06-19 17:29:39,081 [INFO]  Using <class 'predictors.predictor_utils.Arima'> for prediction
2019-06-19 17:29:39,299 [INFO]  Found 9 metrics for ns_id:de4e6d80-ba80-4101-a94f-24d7196f5f2b/vnf_member_index:1
2019-06-19 17:29:39,300 [INFO]  Using <class 'predictors.predictor_utils.Arima'> for prediction
2019-06-19 17:29:39,518 [INFO]  Found 10 metrics for ns_id:de4e6d80-ba80-4101-a94f-24d7196f5f2b/vnf_member_index:1
2019-06-19 17:29:39,518 [INFO]  Using <class 'predictors.predictor_utils.Arima'> for prediction
2019-06-19 17:29:39,734 [INFO]  Found 11 metrics for ns_id:de4e6d80-ba80-4101-a94f-24d7196f5f2b/vnf_member_index:1
2019-06-19 17:29:39,734 [INFO]  Using <class 'predictors.predictor_utils.Arima'> for prediction
2019-06-19 17:29:39,947 [INFO]  Found 12 metrics for ns_id:de4e6d80-ba80-4101-a94f-24d7196f5f2b/vnf_member_index:1
2019-06-19 17:29:39,947 [INFO]  Using <class 'predictors.predictor_utils.Arima'> for prediction
2019-06-19 17:29:40,162 [INFO]  Found 13 metrics for ns_id:de4e6d80-ba80-4101-a94f-24d7196f5f2b/vnf_member_index:1
2019-06-19 17:29:40,162 [INFO]  Using <class 'predictors.predictor_utils.Arima'> for prediction
2019-06-19 17:29:40,379 [INFO]  Found 14 metrics for ns_id:de4e6d80-ba80-4101-a94f-24d7196f5f2b/vnf_member_index:1
2019-06-19 17:29:40,380 [INFO]  Using <class 'predictors.predictor_utils.Arima'> for prediction
2019-06-19 17:29:40,599 [INFO]  Found 15 metrics for ns_id:de4e6d80-ba80-4101-a94f-24d7196f5f2b/vnf_member_index:1
2019-06-19 17:29:40,600 [INFO]  Using <class 'predictors.predictor_utils.Arima'> for prediction
2019-06-19 17:29:40,824 [INFO]  Found 16 metrics for ns_id:de4e6d80-ba80-4101-a94f-24d7196f5f2b/vnf_member_index:1
2019-06-19 17:29:40,824 [INFO]  Using <class 'predictors.predictor_utils.Arima'> for prediction
2019-06-19 17:29:41,039 [INFO]  Found 17 metrics for ns_id:de4e6d80-ba80-4101-a94f-24d7196f5f2b/vnf_member_index:1
2019-06-19 17:29:41,039 [INFO]  Using <class 'predictors.predictor_utils.Arima'> for prediction
2019-06-19 17:29:41,254 [INFO]  Found 18 metrics for ns_id:de4e6d80-ba80-4101-a94f-24d7196f5f2b/vnf_member_index:1
2019-06-19 17:29:41,254 [INFO]  Using <class 'predictors.predictor_utils.Arima'> for prediction
2019-06-19 17:29:41,467 [INFO]  Found 19 metrics for ns_id:de4e6d80-ba80-4101-a94f-24d7196f5f2b/vnf_member_index:1
2019-06-19 17:29:41,468 [INFO]  Using <class 'predictors.predictor_utils.Arima'> for prediction
2019-06-19 17:29:41,686 [INFO]  Found 20 metrics for ns_id:de4e6d80-ba80-4101-a94f-24d7196f5f2b/vnf_member_index:1
2019-06-19 17:29:41,686 [INFO]  Using <class 'predictors.predictor_utils.Arima'> for prediction
2019-06-19 17:29:41,930 [INFO]  Found 21 metrics for ns_id:de4e6d80-ba80-4101-a94f-24d7196f5f2b/vnf_member_index:1
2019-06-19 17:29:41,931 [INFO]  Using <class 'predictors.predictor_utils.Arima'> for prediction
2019-06-19 17:29:42,322 [INFO]  Found 22 metrics for ns_id:de4e6d80-ba80-4101-a94f-24d7196f5f2b/vnf_member_index:1
2019-06-19 17:29:42,323 [INFO]  Using <class 'predictors.predictor_utils.Arima'> for prediction
2019-06-19 17:29:42,553 [INFO]  Found 23 metrics for ns_id:de4e6d80-ba80-4101-a94f-24d7196f5f2b/vnf_member_index:1
2019-06-19 17:29:42,553 [INFO]  Using <class 'predictors.predictor_utils.Arima'> for prediction
2019-06-19 17:29:42,794 [INFO]  Found 24 metrics for ns_id:de4e6d80-ba80-4101-a94f-24d7196f5f2b/vnf_member_index:1
2019-06-19 17:29:42,794 [INFO]  Using <class 'predictors.predictor_utils.Arima'> for prediction
2019-06-19 17:29:43,075 [INFO]  Found 25 metrics for ns_id:de4e6d80-ba80-4101-a94f-24d7196f5f2b/vnf_member_index:1
2019-06-19 17:29:43,075 [INFO]  Using <class 'predictors.predictor_utils.Arima'> for prediction
2019-06-19 17:29:43,351 [INFO]  Found 26 metrics for ns_id:de4e6d80-ba80-4101-a94f-24d7196f5f2b/vnf_member_index:1
2019-06-19 17:29:43,351 [INFO]  Using <class 'predictors.predictor_utils.Arima'> for prediction
2019-06-19 17:29:43,569 [INFO]  Found 27 metrics for ns_id:de4e6d80-ba80-4101-a94f-24d7196f5f2b/vnf_member_index:1
2019-06-19 17:29:43,570 [INFO]  Using <class 'predictors.predictor_utils.Arima'> for prediction
2019-06-19 17:29:43,785 [INFO]  Found 28 metrics for ns_id:de4e6d80-ba80-4101-a94f-24d7196f5f2b/vnf_member_index:1
2019-06-19 17:29:43,785 [INFO]  Using <class 'predictors.predictor_utils.Arima'> for prediction
2019-06-19 17:29:44,006 [INFO]  Found 29 metrics for ns_id:de4e6d80-ba80-4101-a94f-24d7196f5f2b/vnf_member_index:1
2019-06-19 17:29:44,006 [INFO]  Using <class 'predictors.predictor_utils.Arima'> for prediction
2019-06-19 17:29:44,220 [INFO]  Found 30 metrics for ns_id:de4e6d80-ba80-4101-a94f-24d7196f5f2b/vnf_member_index:1
2019-06-19 17:29:44,220 [INFO]  Using <class 'predictors.predictor_utils.Arima'> for prediction
2019-06-19 17:29:44,435 [INFO]  Found 31 metrics for ns_id:de4e6d80-ba80-4101-a94f-24d7196f5f2b/vnf_member_index:1
2019-06-19 17:29:44,435 [INFO]  Using <class 'predictors.predictor_utils.Arima'> for prediction
2019-06-19 17:29:44,697 [INFO]  Found 32 metrics for ns_id:de4e6d80-ba80-4101-a94f-24d7196f5f2b/vnf_member_index:1
2019-06-19 17:29:44,697 [INFO]  Using <class 'predictors.predictor_utils.Arima'> for prediction
2019-06-19 17:29:44,917 [INFO]  Found 33 metrics for ns_id:de4e6d80-ba80-4101-a94f-24d7196f5f2b/vnf_member_index:1
2019-06-19 17:29:44,917 [INFO]  Using <class 'predictors.predictor_utils.Arima'> for prediction
2019-06-19 17:29:45,188 [INFO]  Found 34 metrics for ns_id:de4e6d80-ba80-4101-a94f-24d7196f5f2b/vnf_member_index:1
2019-06-19 17:29:45,188 [INFO]  Using <class 'predictors.predictor_utils.Arima'> for prediction
2019-06-19 17:29:45,405 [INFO]  Found 35 metrics for ns_id:de4e6d80-ba80-4101-a94f-24d7196f5f2b/vnf_member_index:1
2019-06-19 17:29:45,405 [INFO]  Using <class 'predictors.predictor_utils.Arima'> for prediction
2019-06-19 17:29:45,619 [INFO]  Found 36 metrics for ns_id:de4e6d80-ba80-4101-a94f-24d7196f5f2b/vnf_member_index:1
2019-06-19 17:29:45,619 [INFO]  Using <class 'predictors.predictor_utils.Arima'> for prediction
2019-06-19 17:30:24,378 [INFO]  Found 37 metrics for ns_id:de4e6d80-ba80-4101-a94f-24d7196f5f2b/vnf_member_index:1
2019-06-19 17:30:24,378 [INFO]  Using <class 'predictors.predictor_utils.Arima'> for prediction
2019-06-19 17:30:44,743 [INFO]  Found 38 metrics for ns_id:de4e6d80-ba80-4101-a94f-24d7196f5f2b/vnf_member_index:1
2019-06-19 17:30:44,743 [INFO]  Using <class 'predictors.predictor_utils.Arima'> for prediction
2019-06-20 10:22:25,833 [ERROR]  Internal Server Error: /predict/
Traceback (most recent call last):
  File "/Users/ioanniskalyvas/PycharmProjects/5ginfire/prediction/venv/lib/python3.7/site-packages/django/db/models/sql/query.py", line 1768, in add_fields
    join_info = self.setup_joins(name.split(LOOKUP_SEP), opts, alias, allow_many=allow_m2m)
  File "/Users/ioanniskalyvas/PycharmProjects/5ginfire/prediction/venv/lib/python3.7/site-packages/django/db/models/sql/query.py", line 1504, in setup_joins
    names[:pivot], opts, allow_many, fail_on_missing=True,
  File "/Users/ioanniskalyvas/PycharmProjects/5ginfire/prediction/venv/lib/python3.7/site-packages/django/db/models/sql/query.py", line 1420, in names_to_path
    "Choices are: %s" % (name, ", ".join(available)))
django.core.exceptions.FieldError: Cannot resolve keyword '' into field. Choices are: cooldown_period, cpu_load, id, ns_id, scaling_group_descriptor, timestamp, vdu_count, vnf_member_index

During handling of the above exception, another exception occurred:

Traceback (most recent call last):
  File "/Users/ioanniskalyvas/PycharmProjects/5ginfire/prediction/venv/lib/python3.7/site-packages/django/core/handlers/exception.py", line 34, in inner
    response = get_response(request)
  File "/Users/ioanniskalyvas/PycharmProjects/5ginfire/prediction/venv/lib/python3.7/site-packages/django/core/handlers/base.py", line 115, in _get_response
    response = self.process_exception_by_middleware(e, request)
  File "/Users/ioanniskalyvas/PycharmProjects/5ginfire/prediction/venv/lib/python3.7/site-packages/django/core/handlers/base.py", line 113, in _get_response
    response = wrapped_callback(request, *callback_args, **callback_kwargs)
  File "/Users/ioanniskalyvas/PycharmProjects/5ginfire/prediction/venv/lib/python3.7/site-packages/django/views/decorators/csrf.py", line 54, in wrapped_view
    return view_func(*args, **kwargs)
  File "/Users/ioanniskalyvas/PycharmProjects/5ginfire/prediction/venv/lib/python3.7/site-packages/django/views/generic/base.py", line 71, in view
    return self.dispatch(request, *args, **kwargs)
  File "/Users/ioanniskalyvas/PycharmProjects/5ginfire/prediction/venv/lib/python3.7/site-packages/rest_framework/views.py", line 495, in dispatch
    response = self.handle_exception(exc)
  File "/Users/ioanniskalyvas/PycharmProjects/5ginfire/prediction/venv/lib/python3.7/site-packages/rest_framework/views.py", line 455, in handle_exception
    self.raise_uncaught_exception(exc)
  File "/Users/ioanniskalyvas/PycharmProjects/5ginfire/prediction/venv/lib/python3.7/site-packages/rest_framework/views.py", line 492, in dispatch
    response = handler(request, *args, **kwargs)
  File "/Users/ioanniskalyvas/PycharmProjects/5ginfire/prediction/venv/lib/python3.7/site-packages/rest_framework/decorators.py", line 55, in handler
    return func(*args, **kwargs)
  File "/Users/ioanniskalyvas/PycharmProjects/5ginfire/prediction/predictor/predictors/views.py", line 39, in predict
    num_of_metrics = Metric.objects.filter(ns_id=metric.ns_id, vnf_member_index=metric.vnf_member_index).values("ns_id","")
  File "/Users/ioanniskalyvas/PycharmProjects/5ginfire/prediction/venv/lib/python3.7/site-packages/django/db/models/query.py", line 798, in values
    clone = self._values(*fields, **expressions)
  File "/Users/ioanniskalyvas/PycharmProjects/5ginfire/prediction/venv/lib/python3.7/site-packages/django/db/models/query.py", line 793, in _values
    clone.query.set_values(fields)
  File "/Users/ioanniskalyvas/PycharmProjects/5ginfire/prediction/venv/lib/python3.7/site-packages/django/db/models/sql/query.py", line 2020, in set_values
    self.add_fields(field_names, True)
  File "/Users/ioanniskalyvas/PycharmProjects/5ginfire/prediction/venv/lib/python3.7/site-packages/django/db/models/sql/query.py", line 1791, in add_fields
    "Choices are: %s" % (name, ", ".join(names)))
django.core.exceptions.FieldError: Cannot resolve keyword '' into field. Choices are: cooldown_period, cpu_load, id, ns_id, scaling_group_descriptor, timestamp, vdu_count, vnf_member_index
2019-06-20 10:22:48,282 [ERROR]  Internal Server Error: /predict/
Traceback (most recent call last):
  File "/Users/ioanniskalyvas/PycharmProjects/5ginfire/prediction/venv/lib/python3.7/site-packages/django/db/models/sql/query.py", line 1768, in add_fields
    join_info = self.setup_joins(name.split(LOOKUP_SEP), opts, alias, allow_many=allow_m2m)
  File "/Users/ioanniskalyvas/PycharmProjects/5ginfire/prediction/venv/lib/python3.7/site-packages/django/db/models/sql/query.py", line 1504, in setup_joins
    names[:pivot], opts, allow_many, fail_on_missing=True,
  File "/Users/ioanniskalyvas/PycharmProjects/5ginfire/prediction/venv/lib/python3.7/site-packages/django/db/models/sql/query.py", line 1420, in names_to_path
    "Choices are: %s" % (name, ", ".join(available)))
django.core.exceptions.FieldError: Cannot resolve keyword '' into field. Choices are: cooldown_period, cpu_load, id, ns_id, scaling_group_descriptor, timestamp, vdu_count, vnf_member_index

During handling of the above exception, another exception occurred:

Traceback (most recent call last):
  File "/Users/ioanniskalyvas/PycharmProjects/5ginfire/prediction/venv/lib/python3.7/site-packages/django/core/handlers/exception.py", line 34, in inner
    response = get_response(request)
  File "/Users/ioanniskalyvas/PycharmProjects/5ginfire/prediction/venv/lib/python3.7/site-packages/django/core/handlers/base.py", line 115, in _get_response
    response = self.process_exception_by_middleware(e, request)
  File "/Users/ioanniskalyvas/PycharmProjects/5ginfire/prediction/venv/lib/python3.7/site-packages/django/core/handlers/base.py", line 113, in _get_response
    response = wrapped_callback(request, *callback_args, **callback_kwargs)
  File "/Users/ioanniskalyvas/PycharmProjects/5ginfire/prediction/venv/lib/python3.7/site-packages/django/views/decorators/csrf.py", line 54, in wrapped_view
    return view_func(*args, **kwargs)
  File "/Users/ioanniskalyvas/PycharmProjects/5ginfire/prediction/venv/lib/python3.7/site-packages/django/views/generic/base.py", line 71, in view
    return self.dispatch(request, *args, **kwargs)
  File "/Users/ioanniskalyvas/PycharmProjects/5ginfire/prediction/venv/lib/python3.7/site-packages/rest_framework/views.py", line 495, in dispatch
    response = self.handle_exception(exc)
  File "/Users/ioanniskalyvas/PycharmProjects/5ginfire/prediction/venv/lib/python3.7/site-packages/rest_framework/views.py", line 455, in handle_exception
    self.raise_uncaught_exception(exc)
  File "/Users/ioanniskalyvas/PycharmProjects/5ginfire/prediction/venv/lib/python3.7/site-packages/rest_framework/views.py", line 492, in dispatch
    response = handler(request, *args, **kwargs)
  File "/Users/ioanniskalyvas/PycharmProjects/5ginfire/prediction/venv/lib/python3.7/site-packages/rest_framework/decorators.py", line 55, in handler
    return func(*args, **kwargs)
  File "/Users/ioanniskalyvas/PycharmProjects/5ginfire/prediction/predictor/predictors/views.py", line 39, in predict
    num_of_metrics = Metric.objects.filter(ns_id=metric.ns_id, vnf_member_index=metric.vnf_member_index).values("ns_id","")
  File "/Users/ioanniskalyvas/PycharmProjects/5ginfire/prediction/venv/lib/python3.7/site-packages/django/db/models/query.py", line 798, in values
    clone = self._values(*fields, **expressions)
  File "/Users/ioanniskalyvas/PycharmProjects/5ginfire/prediction/venv/lib/python3.7/site-packages/django/db/models/query.py", line 793, in _values
    clone.query.set_values(fields)
  File "/Users/ioanniskalyvas/PycharmProjects/5ginfire/prediction/venv/lib/python3.7/site-packages/django/db/models/sql/query.py", line 2020, in set_values
    self.add_fields(field_names, True)
  File "/Users/ioanniskalyvas/PycharmProjects/5ginfire/prediction/venv/lib/python3.7/site-packages/django/db/models/sql/query.py", line 1791, in add_fields
    "Choices are: %s" % (name, ", ".join(names)))
django.core.exceptions.FieldError: Cannot resolve keyword '' into field. Choices are: cooldown_period, cpu_load, id, ns_id, scaling_group_descriptor, timestamp, vdu_count, vnf_member_index
2019-06-20 10:30:31,128 [INFO]  Found 5 metrics for ns_id:1a/vnf_member_index:1
2019-06-20 10:30:31,128 [INFO]  Using Arima for prediction
2019-06-20 10:32:29,362 [INFO]  Metrics found are <QuerySet [{'ns_id': '1a', 'vnf_member_index': 1, 'cooldown_period': 3.0, 'scaling_group_descriptor': 'vnf_autoscale', 'vdu_count': 3, 'cpu_load': 1.45352}, {'ns_id': '1a', 'vnf_member_index': 1, 'cooldown_period': 3.0, 'scaling_group_descriptor': 'vnf_autoscale', 'vdu_count': 3, 'cpu_load': 1.45352}, {'ns_id': '1a', 'vnf_member_index': 1, 'cooldown_period': 3.0, 'scaling_group_descriptor': 'vnf_autoscale', 'vdu_count': 3, 'cpu_load': 1.45352}, {'ns_id': '1a', 'vnf_member_index': 1, 'cooldown_period': 3.0, 'scaling_group_descriptor': 'vnf_autoscale', 'vdu_count': 3, 'cpu_load': 1.45352}, {'ns_id': '1a', 'vnf_member_index': 1, 'cooldown_period': 3.0, 'scaling_group_descriptor': 'vnf_autoscale', 'vdu_count': 3, 'cpu_load': 1.45352}, {'ns_id': '1a', 'vnf_member_index': 1, 'cooldown_period': 3.0, 'scaling_group_descriptor': 'vnf_autoscale', 'vdu_count': 3, 'cpu_load': 1.45352}]>
2019-06-20 10:32:29,363 [INFO]  Found 6 metrics for ns_id:1a/vnf_member_index:1
2019-06-20 10:32:29,363 [INFO]  Using Arima for prediction
2019-06-20 10:32:59,566 [INFO]  Metrics found are <QuerySet [{'ns_id': '1a', 'vnf_member_index': 1, 'cooldown_period': 3.0, 'scaling_group_descriptor': 'vnf_autoscale', 'vdu_count': 3, 'cpu_load': 1.45352, 'timestamp': datetime.datetime(2010, 6, 20, 10, 10, 10, tzinfo=<UTC>)}, {'ns_id': '1a', 'vnf_member_index': 1, 'cooldown_period': 3.0, 'scaling_group_descriptor': 'vnf_autoscale', 'vdu_count': 3, 'cpu_load': 1.45352, 'timestamp': datetime.datetime(2014, 6, 20, 10, 10, 10, tzinfo=<UTC>)}, {'ns_id': '1a', 'vnf_member_index': 1, 'cooldown_period': 3.0, 'scaling_group_descriptor': 'vnf_autoscale', 'vdu_count': 3, 'cpu_load': 1.45352, 'timestamp': datetime.datetime(2020, 6, 20, 10, 10, 10, tzinfo=<UTC>)}, {'ns_id': '1a', 'vnf_member_index': 1, 'cooldown_period': 3.0, 'scaling_group_descriptor': 'vnf_autoscale', 'vdu_count': 3, 'cpu_load': 1.45352, 'timestamp': datetime.datetime(2020, 6, 20, 10, 10, 10, tzinfo=<UTC>)}, {'ns_id': '1a', 'vnf_member_index': 1, 'cooldown_period': 3.0, 'scaling_group_descriptor': 'vnf_autoscale', 'vdu_count': 3, 'cpu_load': 1.45352, 'timestamp': datetime.datetime(2020, 6, 20, 10, 10, 10, tzinfo=<UTC>)}, {'ns_id': '1a', 'vnf_member_index': 1, 'cooldown_period': 3.0, 'scaling_group_descriptor': 'vnf_autoscale', 'vdu_count': 3, 'cpu_load': 1.45352, 'timestamp': datetime.datetime(2020, 6, 20, 10, 10, 10, tzinfo=<UTC>)}, {'ns_id': '1a', 'vnf_member_index': 1, 'cooldown_period': 3.0, 'scaling_group_descriptor': 'vnf_autoscale', 'vdu_count': 3, 'cpu_load': 1.45352, 'timestamp': datetime.datetime(2020, 6, 20, 10, 10, 10, tzinfo=<UTC>)}]>
2019-06-20 10:32:59,568 [INFO]  Found 7 metrics for ns_id:1a/vnf_member_index:1
2019-06-20 10:32:59,568 [INFO]  Using Arima for prediction
2019-06-20 10:47:55,784 [INFO]  Found 8 metrics for ns_id:1a/vnf_member_index:1
2019-06-20 10:47:55,785 [INFO]  Using Arima for prediction
2019-06-20 10:47:55,859 [ERROR]  Internal Server Error: /predict/
Traceback (most recent call last):
  File "/Users/ioanniskalyvas/PycharmProjects/5ginfire/prediction/venv/lib/python3.7/site-packages/django/core/handlers/exception.py", line 34, in inner
    response = get_response(request)
  File "/Users/ioanniskalyvas/PycharmProjects/5ginfire/prediction/venv/lib/python3.7/site-packages/django/core/handlers/base.py", line 115, in _get_response
    response = self.process_exception_by_middleware(e, request)
  File "/Users/ioanniskalyvas/PycharmProjects/5ginfire/prediction/venv/lib/python3.7/site-packages/django/core/handlers/base.py", line 113, in _get_response
    response = wrapped_callback(request, *callback_args, **callback_kwargs)
  File "/Users/ioanniskalyvas/PycharmProjects/5ginfire/prediction/venv/lib/python3.7/site-packages/django/views/decorators/csrf.py", line 54, in wrapped_view
    return view_func(*args, **kwargs)
  File "/Users/ioanniskalyvas/PycharmProjects/5ginfire/prediction/venv/lib/python3.7/site-packages/django/views/generic/base.py", line 71, in view
    return self.dispatch(request, *args, **kwargs)
  File "/Users/ioanniskalyvas/PycharmProjects/5ginfire/prediction/venv/lib/python3.7/site-packages/rest_framework/views.py", line 495, in dispatch
    response = self.handle_exception(exc)
  File "/Users/ioanniskalyvas/PycharmProjects/5ginfire/prediction/venv/lib/python3.7/site-packages/rest_framework/views.py", line 455, in handle_exception
    self.raise_uncaught_exception(exc)
  File "/Users/ioanniskalyvas/PycharmProjects/5ginfire/prediction/venv/lib/python3.7/site-packages/rest_framework/views.py", line 492, in dispatch
    response = handler(request, *args, **kwargs)
  File "/Users/ioanniskalyvas/PycharmProjects/5ginfire/prediction/venv/lib/python3.7/site-packages/rest_framework/decorators.py", line 55, in handler
    return func(*args, **kwargs)
  File "/Users/ioanniskalyvas/PycharmProjects/5ginfire/prediction/predictor/predictors/views.py", line 47, in predict
    ns_id = num_of_metrics[-1]["ns_id"]
  File "/Users/ioanniskalyvas/PycharmProjects/5ginfire/prediction/venv/lib/python3.7/site-packages/django/db/models/query.py", line 288, in __getitem__
    "Negative indexing is not supported."
AssertionError: Negative indexing is not supported.
2019-06-20 10:53:22,334 [INFO]  Found 9 metrics for ns_id:1a/vnf_member_index:1
2019-06-20 10:53:22,335 [INFO]  Using Arima for prediction
2019-06-20 10:53:22,365 [ERROR]  Internal Server Error: /predict/
Traceback (most recent call last):
  File "/Users/ioanniskalyvas/PycharmProjects/5ginfire/prediction/venv/lib/python3.7/site-packages/django/core/handlers/exception.py", line 34, in inner
    response = get_response(request)
  File "/Users/ioanniskalyvas/PycharmProjects/5ginfire/prediction/venv/lib/python3.7/site-packages/django/core/handlers/base.py", line 115, in _get_response
    response = self.process_exception_by_middleware(e, request)
  File "/Users/ioanniskalyvas/PycharmProjects/5ginfire/prediction/venv/lib/python3.7/site-packages/django/core/handlers/base.py", line 113, in _get_response
    response = wrapped_callback(request, *callback_args, **callback_kwargs)
  File "/Users/ioanniskalyvas/PycharmProjects/5ginfire/prediction/venv/lib/python3.7/site-packages/django/views/decorators/csrf.py", line 54, in wrapped_view
    return view_func(*args, **kwargs)
  File "/Users/ioanniskalyvas/PycharmProjects/5ginfire/prediction/venv/lib/python3.7/site-packages/django/views/generic/base.py", line 71, in view
    return self.dispatch(request, *args, **kwargs)
  File "/Users/ioanniskalyvas/PycharmProjects/5ginfire/prediction/venv/lib/python3.7/site-packages/rest_framework/views.py", line 495, in dispatch
    response = self.handle_exception(exc)
  File "/Users/ioanniskalyvas/PycharmProjects/5ginfire/prediction/venv/lib/python3.7/site-packages/rest_framework/views.py", line 455, in handle_exception
    self.raise_uncaught_exception(exc)
  File "/Users/ioanniskalyvas/PycharmProjects/5ginfire/prediction/venv/lib/python3.7/site-packages/rest_framework/views.py", line 492, in dispatch
    response = handler(request, *args, **kwargs)
  File "/Users/ioanniskalyvas/PycharmProjects/5ginfire/prediction/venv/lib/python3.7/site-packages/rest_framework/decorators.py", line 55, in handler
    return func(*args, **kwargs)
  File "/Users/ioanniskalyvas/PycharmProjects/5ginfire/prediction/predictor/predictors/views.py", line 48, in predict
    vdu_count = [metric["vdu_count"] for metric in num_of_metrics].reverse()[0] # pass in the latest vdu count of the group of metrics to predictor
TypeError: 'NoneType' object is not subscriptable
2019-06-20 10:53:53,363 [INFO]  Found 10 metrics for ns_id:1a/vnf_member_index:1
2019-06-20 10:53:53,365 [INFO]  Using Arima for prediction
2019-06-20 11:09:12,352 [INFO]  Found 11 metrics for ns_id:1a/vnf_member_index:1
2019-06-20 11:09:12,353 [INFO]  Using Arima for prediction
2019-06-20 11:09:12,373 [ERROR]  Internal Server Error: /predict/
Traceback (most recent call last):
  File "/Users/ioanniskalyvas/PycharmProjects/5ginfire/prediction/venv/lib/python3.7/site-packages/django/core/handlers/exception.py", line 34, in inner
    response = get_response(request)
  File "/Users/ioanniskalyvas/PycharmProjects/5ginfire/prediction/venv/lib/python3.7/site-packages/django/core/handlers/base.py", line 115, in _get_response
    response = self.process_exception_by_middleware(e, request)
  File "/Users/ioanniskalyvas/PycharmProjects/5ginfire/prediction/venv/lib/python3.7/site-packages/django/core/handlers/base.py", line 113, in _get_response
    response = wrapped_callback(request, *callback_args, **callback_kwargs)
  File "/Users/ioanniskalyvas/PycharmProjects/5ginfire/prediction/venv/lib/python3.7/site-packages/django/views/decorators/csrf.py", line 54, in wrapped_view
    return view_func(*args, **kwargs)
  File "/Users/ioanniskalyvas/PycharmProjects/5ginfire/prediction/venv/lib/python3.7/site-packages/django/views/generic/base.py", line 71, in view
    return self.dispatch(request, *args, **kwargs)
  File "/Users/ioanniskalyvas/PycharmProjects/5ginfire/prediction/venv/lib/python3.7/site-packages/rest_framework/views.py", line 495, in dispatch
    response = self.handle_exception(exc)
  File "/Users/ioanniskalyvas/PycharmProjects/5ginfire/prediction/venv/lib/python3.7/site-packages/rest_framework/views.py", line 455, in handle_exception
    self.raise_uncaught_exception(exc)
  File "/Users/ioanniskalyvas/PycharmProjects/5ginfire/prediction/venv/lib/python3.7/site-packages/rest_framework/views.py", line 492, in dispatch
    response = handler(request, *args, **kwargs)
  File "/Users/ioanniskalyvas/PycharmProjects/5ginfire/prediction/venv/lib/python3.7/site-packages/rest_framework/decorators.py", line 55, in handler
    return func(*args, **kwargs)
  File "/Users/ioanniskalyvas/PycharmProjects/5ginfire/prediction/predictor/predictors/views.py", line 62, in predict
    pr_model.predict(data)
TypeError: predict() missing 1 required positional argument: 'data'
2019-06-20 11:09:41,025 [INFO]  Found 12 metrics for ns_id:1a/vnf_member_index:1
2019-06-20 11:09:41,025 [INFO]  Using Arima for prediction
2019-06-20 11:09:41,042 [ERROR]  Internal Server Error: /predict/
Traceback (most recent call last):
  File "/Users/ioanniskalyvas/PycharmProjects/5ginfire/prediction/venv/lib/python3.7/site-packages/django/core/handlers/exception.py", line 34, in inner
    response = get_response(request)
  File "/Users/ioanniskalyvas/PycharmProjects/5ginfire/prediction/venv/lib/python3.7/site-packages/django/core/handlers/base.py", line 115, in _get_response
    response = self.process_exception_by_middleware(e, request)
  File "/Users/ioanniskalyvas/PycharmProjects/5ginfire/prediction/venv/lib/python3.7/site-packages/django/core/handlers/base.py", line 113, in _get_response
    response = wrapped_callback(request, *callback_args, **callback_kwargs)
  File "/Users/ioanniskalyvas/PycharmProjects/5ginfire/prediction/venv/lib/python3.7/site-packages/django/views/decorators/csrf.py", line 54, in wrapped_view
    return view_func(*args, **kwargs)
  File "/Users/ioanniskalyvas/PycharmProjects/5ginfire/prediction/venv/lib/python3.7/site-packages/django/views/generic/base.py", line 71, in view
    return self.dispatch(request, *args, **kwargs)
  File "/Users/ioanniskalyvas/PycharmProjects/5ginfire/prediction/venv/lib/python3.7/site-packages/rest_framework/views.py", line 495, in dispatch
    response = self.handle_exception(exc)
  File "/Users/ioanniskalyvas/PycharmProjects/5ginfire/prediction/venv/lib/python3.7/site-packages/rest_framework/views.py", line 455, in handle_exception
    self.raise_uncaught_exception(exc)
  File "/Users/ioanniskalyvas/PycharmProjects/5ginfire/prediction/venv/lib/python3.7/site-packages/rest_framework/views.py", line 492, in dispatch
    response = handler(request, *args, **kwargs)
  File "/Users/ioanniskalyvas/PycharmProjects/5ginfire/prediction/venv/lib/python3.7/site-packages/rest_framework/decorators.py", line 55, in handler
    return func(*args, **kwargs)
  File "/Users/ioanniskalyvas/PycharmProjects/5ginfire/prediction/predictor/predictors/views.py", line 62, in predict
    pr_model.predict(data=data)
TypeError: predict() missing 1 required positional argument: 'self'
2019-06-20 11:10:36,197 [INFO]  Found 13 metrics for ns_id:1a/vnf_member_index:1
2019-06-20 11:10:36,197 [INFO]  Using Arima for prediction
2019-06-20 11:10:36,197 [INFO]  Start predicting with Arima
2019-06-20 11:10:36,197 [INFO]  Will train with 13 values
2019-06-20 11:10:36,241 [ERROR]  Internal Server Error: /predict/
Traceback (most recent call last):
  File "/Users/ioanniskalyvas/PycharmProjects/5ginfire/prediction/venv/lib/python3.7/site-packages/django/core/handlers/exception.py", line 34, in inner
    response = get_response(request)
  File "/Users/ioanniskalyvas/PycharmProjects/5ginfire/prediction/venv/lib/python3.7/site-packages/django/core/handlers/base.py", line 115, in _get_response
    response = self.process_exception_by_middleware(e, request)
  File "/Users/ioanniskalyvas/PycharmProjects/5ginfire/prediction/venv/lib/python3.7/site-packages/django/core/handlers/base.py", line 113, in _get_response
    response = wrapped_callback(request, *callback_args, **callback_kwargs)
  File "/Users/ioanniskalyvas/PycharmProjects/5ginfire/prediction/venv/lib/python3.7/site-packages/django/views/decorators/csrf.py", line 54, in wrapped_view
    return view_func(*args, **kwargs)
  File "/Users/ioanniskalyvas/PycharmProjects/5ginfire/prediction/venv/lib/python3.7/site-packages/django/views/generic/base.py", line 71, in view
    return self.dispatch(request, *args, **kwargs)
  File "/Users/ioanniskalyvas/PycharmProjects/5ginfire/prediction/venv/lib/python3.7/site-packages/rest_framework/views.py", line 495, in dispatch
    response = self.handle_exception(exc)
  File "/Users/ioanniskalyvas/PycharmProjects/5ginfire/prediction/venv/lib/python3.7/site-packages/rest_framework/views.py", line 455, in handle_exception
    self.raise_uncaught_exception(exc)
  File "/Users/ioanniskalyvas/PycharmProjects/5ginfire/prediction/venv/lib/python3.7/site-packages/rest_framework/views.py", line 492, in dispatch
    response = handler(request, *args, **kwargs)
  File "/Users/ioanniskalyvas/PycharmProjects/5ginfire/prediction/venv/lib/python3.7/site-packages/rest_framework/decorators.py", line 55, in handler
    return func(*args, **kwargs)
  File "/Users/ioanniskalyvas/PycharmProjects/5ginfire/prediction/predictor/predictors/views.py", line 62, in predict
    pr_model().predict(data)
  File "/Users/ioanniskalyvas/PycharmProjects/5ginfire/prediction/predictor/predictors/predictor_utils.py", line 154, in predict
    model_fit = model.fit(disp=False)
  File "/Users/ioanniskalyvas/PycharmProjects/5ginfire/prediction/venv/lib/python3.7/site-packages/statsmodels/tsa/arima_model.py", line 1157, in fit
    callback, start_ar_lags, **kwargs)
  File "/Users/ioanniskalyvas/PycharmProjects/5ginfire/prediction/venv/lib/python3.7/site-packages/statsmodels/tsa/arima_model.py", line 946, in fit
    start_ar_lags)
  File "/Users/ioanniskalyvas/PycharmProjects/5ginfire/prediction/venv/lib/python3.7/site-packages/statsmodels/tsa/arima_model.py", line 562, in _fit_start_params
    start_params = self._fit_start_params_hr(order, start_ar_lags)
  File "/Users/ioanniskalyvas/PycharmProjects/5ginfire/prediction/venv/lib/python3.7/site-packages/statsmodels/tsa/arima_model.py", line 535, in _fit_start_params_hr
    arcoefs = yule_walker(endog, order=p)[0]
  File "/Users/ioanniskalyvas/PycharmProjects/5ginfire/prediction/venv/lib/python3.7/site-packages/statsmodels/regression/linear_model.py", line 1278, in yule_walker
    rho = np.linalg.solve(R, r[1:])
  File "/Users/ioanniskalyvas/PycharmProjects/5ginfire/prediction/venv/lib/python3.7/site-packages/numpy/linalg/linalg.py", line 403, in solve
    r = gufunc(a, b, signature=signature, extobj=extobj)
  File "/Users/ioanniskalyvas/PycharmProjects/5ginfire/prediction/venv/lib/python3.7/site-packages/numpy/linalg/linalg.py", line 97, in _raise_linalgerror_singular
    raise LinAlgError("Singular matrix")
numpy.linalg.LinAlgError: Singular matrix
2019-06-20 11:16:44,645 [INFO]  Found 14 metrics for ns_id:1a/vnf_member_index:1
2019-06-20 11:16:44,646 [INFO]  Using Arima for prediction
2019-06-20 11:16:44,646 [INFO]  Start predicting with Arima
2019-06-20 11:16:44,646 [INFO]  Will train with 14 values
2019-06-20 11:16:44,665 [ERROR]  Internal Server Error: /predict/
Traceback (most recent call last):
  File "/Users/ioanniskalyvas/PycharmProjects/5ginfire/prediction/venv/lib/python3.7/site-packages/django/core/handlers/exception.py", line 34, in inner
    response = get_response(request)
  File "/Users/ioanniskalyvas/PycharmProjects/5ginfire/prediction/venv/lib/python3.7/site-packages/django/core/handlers/base.py", line 115, in _get_response
    response = self.process_exception_by_middleware(e, request)
  File "/Users/ioanniskalyvas/PycharmProjects/5ginfire/prediction/venv/lib/python3.7/site-packages/django/core/handlers/base.py", line 113, in _get_response
    response = wrapped_callback(request, *callback_args, **callback_kwargs)
  File "/Users/ioanniskalyvas/PycharmProjects/5ginfire/prediction/venv/lib/python3.7/site-packages/django/views/decorators/csrf.py", line 54, in wrapped_view
    return view_func(*args, **kwargs)
  File "/Users/ioanniskalyvas/PycharmProjects/5ginfire/prediction/venv/lib/python3.7/site-packages/django/views/generic/base.py", line 71, in view
    return self.dispatch(request, *args, **kwargs)
  File "/Users/ioanniskalyvas/PycharmProjects/5ginfire/prediction/venv/lib/python3.7/site-packages/rest_framework/views.py", line 495, in dispatch
    response = self.handle_exception(exc)
  File "/Users/ioanniskalyvas/PycharmProjects/5ginfire/prediction/venv/lib/python3.7/site-packages/rest_framework/views.py", line 455, in handle_exception
    self.raise_uncaught_exception(exc)
  File "/Users/ioanniskalyvas/PycharmProjects/5ginfire/prediction/venv/lib/python3.7/site-packages/rest_framework/views.py", line 492, in dispatch
    response = handler(request, *args, **kwargs)
  File "/Users/ioanniskalyvas/PycharmProjects/5ginfire/prediction/venv/lib/python3.7/site-packages/rest_framework/decorators.py", line 55, in handler
    return func(*args, **kwargs)
  File "/Users/ioanniskalyvas/PycharmProjects/5ginfire/prediction/predictor/predictors/views.py", line 62, in predict
    pr_model().predict(data)
  File "/Users/ioanniskalyvas/PycharmProjects/5ginfire/prediction/predictor/predictors/predictor_utils.py", line 154, in predict
    model_fit = model.fit(disp=False)
  File "/Users/ioanniskalyvas/PycharmProjects/5ginfire/prediction/venv/lib/python3.7/site-packages/statsmodels/tsa/arima_model.py", line 1157, in fit
    callback, start_ar_lags, **kwargs)
  File "/Users/ioanniskalyvas/PycharmProjects/5ginfire/prediction/venv/lib/python3.7/site-packages/statsmodels/tsa/arima_model.py", line 946, in fit
    start_ar_lags)
  File "/Users/ioanniskalyvas/PycharmProjects/5ginfire/prediction/venv/lib/python3.7/site-packages/statsmodels/tsa/arima_model.py", line 562, in _fit_start_params
    start_params = self._fit_start_params_hr(order, start_ar_lags)
  File "/Users/ioanniskalyvas/PycharmProjects/5ginfire/prediction/venv/lib/python3.7/site-packages/statsmodels/tsa/arima_model.py", line 535, in _fit_start_params_hr
    arcoefs = yule_walker(endog, order=p)[0]
  File "/Users/ioanniskalyvas/PycharmProjects/5ginfire/prediction/venv/lib/python3.7/site-packages/statsmodels/regression/linear_model.py", line 1278, in yule_walker
    rho = np.linalg.solve(R, r[1:])
  File "/Users/ioanniskalyvas/PycharmProjects/5ginfire/prediction/venv/lib/python3.7/site-packages/numpy/linalg/linalg.py", line 403, in solve
    r = gufunc(a, b, signature=signature, extobj=extobj)
  File "/Users/ioanniskalyvas/PycharmProjects/5ginfire/prediction/venv/lib/python3.7/site-packages/numpy/linalg/linalg.py", line 97, in _raise_linalgerror_singular
    raise LinAlgError("Singular matrix")
numpy.linalg.LinAlgError: Singular matrix
2019-06-20 11:17:11,291 [INFO]  Found 15 metrics for ns_id:1a/vnf_member_index:1
2019-06-20 11:17:11,292 [INFO]  Using Arima for prediction
2019-06-20 11:39:21,327 [INFO]  Found 16 metrics for ns_id:1a/vnf_member_index:1
2019-06-20 11:39:21,328 [INFO]  Using Arima for prediction
2019-06-20 11:39:21,328 [INFO]  Start predicting with Arima
2019-06-20 11:39:21,328 [INFO]  Will train with 16 values
2019-06-20 11:39:21,359 [ERROR]  Internal Server Error: /predict/
Traceback (most recent call last):
  File "/Users/ioanniskalyvas/PycharmProjects/5ginfire/prediction/predictor/predictors/predictor_utils.py", line 156, in predict
    model_fit = model.fit(disp=False)
  File "/Users/ioanniskalyvas/PycharmProjects/5ginfire/prediction/venv/lib/python3.7/site-packages/statsmodels/tsa/arima_model.py", line 1157, in fit
    callback, start_ar_lags, **kwargs)
  File "/Users/ioanniskalyvas/PycharmProjects/5ginfire/prediction/venv/lib/python3.7/site-packages/statsmodels/tsa/arima_model.py", line 946, in fit
    start_ar_lags)
  File "/Users/ioanniskalyvas/PycharmProjects/5ginfire/prediction/venv/lib/python3.7/site-packages/statsmodels/tsa/arima_model.py", line 562, in _fit_start_params
    start_params = self._fit_start_params_hr(order, start_ar_lags)
  File "/Users/ioanniskalyvas/PycharmProjects/5ginfire/prediction/venv/lib/python3.7/site-packages/statsmodels/tsa/arima_model.py", line 535, in _fit_start_params_hr
    arcoefs = yule_walker(endog, order=p)[0]
  File "/Users/ioanniskalyvas/PycharmProjects/5ginfire/prediction/venv/lib/python3.7/site-packages/statsmodels/regression/linear_model.py", line 1278, in yule_walker
    rho = np.linalg.solve(R, r[1:])
  File "/Users/ioanniskalyvas/PycharmProjects/5ginfire/prediction/venv/lib/python3.7/site-packages/numpy/linalg/linalg.py", line 403, in solve
    r = gufunc(a, b, signature=signature, extobj=extobj)
  File "/Users/ioanniskalyvas/PycharmProjects/5ginfire/prediction/venv/lib/python3.7/site-packages/numpy/linalg/linalg.py", line 97, in _raise_linalgerror_singular
    raise LinAlgError("Singular matrix")
numpy.linalg.LinAlgError: Singular matrix

During handling of the above exception, another exception occurred:

Traceback (most recent call last):
  File "/Users/ioanniskalyvas/PycharmProjects/5ginfire/prediction/venv/lib/python3.7/site-packages/django/core/handlers/exception.py", line 34, in inner
    response = get_response(request)
  File "/Users/ioanniskalyvas/PycharmProjects/5ginfire/prediction/venv/lib/python3.7/site-packages/django/core/handlers/base.py", line 115, in _get_response
    response = self.process_exception_by_middleware(e, request)
  File "/Users/ioanniskalyvas/PycharmProjects/5ginfire/prediction/venv/lib/python3.7/site-packages/django/core/handlers/base.py", line 113, in _get_response
    response = wrapped_callback(request, *callback_args, **callback_kwargs)
  File "/Users/ioanniskalyvas/PycharmProjects/5ginfire/prediction/venv/lib/python3.7/site-packages/django/views/decorators/csrf.py", line 54, in wrapped_view
    return view_func(*args, **kwargs)
  File "/Users/ioanniskalyvas/PycharmProjects/5ginfire/prediction/venv/lib/python3.7/site-packages/django/views/generic/base.py", line 71, in view
    return self.dispatch(request, *args, **kwargs)
  File "/Users/ioanniskalyvas/PycharmProjects/5ginfire/prediction/venv/lib/python3.7/site-packages/rest_framework/views.py", line 495, in dispatch
    response = self.handle_exception(exc)
  File "/Users/ioanniskalyvas/PycharmProjects/5ginfire/prediction/venv/lib/python3.7/site-packages/rest_framework/views.py", line 455, in handle_exception
    self.raise_uncaught_exception(exc)
  File "/Users/ioanniskalyvas/PycharmProjects/5ginfire/prediction/venv/lib/python3.7/site-packages/rest_framework/views.py", line 492, in dispatch
    response = handler(request, *args, **kwargs)
  File "/Users/ioanniskalyvas/PycharmProjects/5ginfire/prediction/venv/lib/python3.7/site-packages/rest_framework/decorators.py", line 55, in handler
    return func(*args, **kwargs)
  File "/Users/ioanniskalyvas/PycharmProjects/5ginfire/prediction/predictor/predictors/views.py", line 62, in predict
    pr_model().predict(data)
  File "/Users/ioanniskalyvas/PycharmProjects/5ginfire/prediction/predictor/predictors/predictor_utils.py", line 158, in predict
    assert len(set(cpu_load)) == len(cpu_load), "cpu_load values are not all the same!!!"
AssertionError: cpu_load values are not all the same!!!
2019-06-20 11:39:53,201 [INFO]  Found 17 metrics for ns_id:1a/vnf_member_index:1
2019-06-20 11:39:53,203 [INFO]  Using Arima for prediction
2019-06-20 11:40:03,123 [INFO]  Start predicting with Arima
2019-06-20 11:40:05,555 [INFO]  Will train with 17 values
2019-06-20 11:40:11,229 [ERROR]  Singular matrix detected.All metric values must be the same.Adding noise to overcome
Traceback (most recent call last):
  File "/Users/ioanniskalyvas/PycharmProjects/5ginfire/prediction/predictor/predictors/predictor_utils.py", line 156, in predict
    model_fit = model.fit(disp=False)
  File "/Users/ioanniskalyvas/PycharmProjects/5ginfire/prediction/venv/lib/python3.7/site-packages/statsmodels/tsa/arima_model.py", line 1157, in fit
    callback, start_ar_lags, **kwargs)
  File "/Users/ioanniskalyvas/PycharmProjects/5ginfire/prediction/venv/lib/python3.7/site-packages/statsmodels/tsa/arima_model.py", line 946, in fit
    start_ar_lags)
  File "/Users/ioanniskalyvas/PycharmProjects/5ginfire/prediction/venv/lib/python3.7/site-packages/statsmodels/tsa/arima_model.py", line 562, in _fit_start_params
    start_params = self._fit_start_params_hr(order, start_ar_lags)
  File "/Users/ioanniskalyvas/PycharmProjects/5ginfire/prediction/venv/lib/python3.7/site-packages/statsmodels/tsa/arima_model.py", line 535, in _fit_start_params_hr
    arcoefs = yule_walker(endog, order=p)[0]
  File "/Users/ioanniskalyvas/PycharmProjects/5ginfire/prediction/venv/lib/python3.7/site-packages/statsmodels/regression/linear_model.py", line 1278, in yule_walker
    rho = np.linalg.solve(R, r[1:])
  File "/Users/ioanniskalyvas/PycharmProjects/5ginfire/prediction/venv/lib/python3.7/site-packages/numpy/linalg/linalg.py", line 403, in solve
    r = gufunc(a, b, signature=signature, extobj=extobj)
  File "/Users/ioanniskalyvas/PycharmProjects/5ginfire/prediction/venv/lib/python3.7/site-packages/numpy/linalg/linalg.py", line 97, in _raise_linalgerror_singular
    raise LinAlgError("Singular matrix")
numpy.linalg.LinAlgError: Singular matrix
2019-06-20 11:42:08,261 [INFO]  Found 18 metrics for ns_id:1a/vnf_member_index:1
2019-06-20 11:42:08,262 [INFO]  Using Arima for prediction
2019-06-20 11:42:08,262 [INFO]  Start predicting with Arima
2019-06-20 11:42:08,262 [INFO]  Will train with 18 values
2019-06-20 11:42:08,264 [ERROR]  Singular matrix detected.All metric values must be the same.Adding noise to overcome
Traceback (most recent call last):
  File "/Users/ioanniskalyvas/PycharmProjects/5ginfire/prediction/predictor/predictors/predictor_utils.py", line 156, in predict
    model_fit = model.fit(disp=False)
  File "/Users/ioanniskalyvas/PycharmProjects/5ginfire/prediction/venv/lib/python3.7/site-packages/statsmodels/tsa/arima_model.py", line 1157, in fit
    callback, start_ar_lags, **kwargs)
  File "/Users/ioanniskalyvas/PycharmProjects/5ginfire/prediction/venv/lib/python3.7/site-packages/statsmodels/tsa/arima_model.py", line 946, in fit
    start_ar_lags)
  File "/Users/ioanniskalyvas/PycharmProjects/5ginfire/prediction/venv/lib/python3.7/site-packages/statsmodels/tsa/arima_model.py", line 562, in _fit_start_params
    start_params = self._fit_start_params_hr(order, start_ar_lags)
  File "/Users/ioanniskalyvas/PycharmProjects/5ginfire/prediction/venv/lib/python3.7/site-packages/statsmodels/tsa/arima_model.py", line 535, in _fit_start_params_hr
    arcoefs = yule_walker(endog, order=p)[0]
  File "/Users/ioanniskalyvas/PycharmProjects/5ginfire/prediction/venv/lib/python3.7/site-packages/statsmodels/regression/linear_model.py", line 1278, in yule_walker
    rho = np.linalg.solve(R, r[1:])
  File "/Users/ioanniskalyvas/PycharmProjects/5ginfire/prediction/venv/lib/python3.7/site-packages/numpy/linalg/linalg.py", line 403, in solve
    r = gufunc(a, b, signature=signature, extobj=extobj)
  File "/Users/ioanniskalyvas/PycharmProjects/5ginfire/prediction/venv/lib/python3.7/site-packages/numpy/linalg/linalg.py", line 97, in _raise_linalgerror_singular
    raise LinAlgError("Singular matrix")
numpy.linalg.LinAlgError: Singular matrix
2019-06-20 11:42:08,297 [ERROR]  Internal Server Error: /predict/
Traceback (most recent call last):
  File "/Users/ioanniskalyvas/PycharmProjects/5ginfire/prediction/predictor/predictors/predictor_utils.py", line 156, in predict
    model_fit = model.fit(disp=False)
  File "/Users/ioanniskalyvas/PycharmProjects/5ginfire/prediction/venv/lib/python3.7/site-packages/statsmodels/tsa/arima_model.py", line 1157, in fit
    callback, start_ar_lags, **kwargs)
  File "/Users/ioanniskalyvas/PycharmProjects/5ginfire/prediction/venv/lib/python3.7/site-packages/statsmodels/tsa/arima_model.py", line 946, in fit
    start_ar_lags)
  File "/Users/ioanniskalyvas/PycharmProjects/5ginfire/prediction/venv/lib/python3.7/site-packages/statsmodels/tsa/arima_model.py", line 562, in _fit_start_params
    start_params = self._fit_start_params_hr(order, start_ar_lags)
  File "/Users/ioanniskalyvas/PycharmProjects/5ginfire/prediction/venv/lib/python3.7/site-packages/statsmodels/tsa/arima_model.py", line 535, in _fit_start_params_hr
    arcoefs = yule_walker(endog, order=p)[0]
  File "/Users/ioanniskalyvas/PycharmProjects/5ginfire/prediction/venv/lib/python3.7/site-packages/statsmodels/regression/linear_model.py", line 1278, in yule_walker
    rho = np.linalg.solve(R, r[1:])
  File "/Users/ioanniskalyvas/PycharmProjects/5ginfire/prediction/venv/lib/python3.7/site-packages/numpy/linalg/linalg.py", line 403, in solve
    r = gufunc(a, b, signature=signature, extobj=extobj)
  File "/Users/ioanniskalyvas/PycharmProjects/5ginfire/prediction/venv/lib/python3.7/site-packages/numpy/linalg/linalg.py", line 97, in _raise_linalgerror_singular
    raise LinAlgError("Singular matrix")
numpy.linalg.LinAlgError: Singular matrix

During handling of the above exception, another exception occurred:

Traceback (most recent call last):
  File "/Users/ioanniskalyvas/PycharmProjects/5ginfire/prediction/venv/lib/python3.7/site-packages/django/core/handlers/exception.py", line 34, in inner
    response = get_response(request)
  File "/Users/ioanniskalyvas/PycharmProjects/5ginfire/prediction/venv/lib/python3.7/site-packages/django/core/handlers/base.py", line 115, in _get_response
    response = self.process_exception_by_middleware(e, request)
  File "/Users/ioanniskalyvas/PycharmProjects/5ginfire/prediction/venv/lib/python3.7/site-packages/django/core/handlers/base.py", line 113, in _get_response
    response = wrapped_callback(request, *callback_args, **callback_kwargs)
  File "/Users/ioanniskalyvas/PycharmProjects/5ginfire/prediction/venv/lib/python3.7/site-packages/django/views/decorators/csrf.py", line 54, in wrapped_view
    return view_func(*args, **kwargs)
  File "/Users/ioanniskalyvas/PycharmProjects/5ginfire/prediction/venv/lib/python3.7/site-packages/django/views/generic/base.py", line 71, in view
    return self.dispatch(request, *args, **kwargs)
  File "/Users/ioanniskalyvas/PycharmProjects/5ginfire/prediction/venv/lib/python3.7/site-packages/rest_framework/views.py", line 495, in dispatch
    response = self.handle_exception(exc)
  File "/Users/ioanniskalyvas/PycharmProjects/5ginfire/prediction/venv/lib/python3.7/site-packages/rest_framework/views.py", line 455, in handle_exception
    self.raise_uncaught_exception(exc)
  File "/Users/ioanniskalyvas/PycharmProjects/5ginfire/prediction/venv/lib/python3.7/site-packages/rest_framework/views.py", line 492, in dispatch
    response = handler(request, *args, **kwargs)
  File "/Users/ioanniskalyvas/PycharmProjects/5ginfire/prediction/venv/lib/python3.7/site-packages/rest_framework/decorators.py", line 55, in handler
    return func(*args, **kwargs)
  File "/Users/ioanniskalyvas/PycharmProjects/5ginfire/prediction/predictor/predictors/views.py", line 62, in predict
    pr_model().predict(data)
  File "/Users/ioanniskalyvas/PycharmProjects/5ginfire/prediction/predictor/predictors/predictor_utils.py", line 160, in predict
    model = ARIMA(cpu_load + 0.00001*np.random.rand(1, len(cpu_load)[0]), order=(1, 1, 0))
TypeError: 'int' object is not subscriptable
2019-06-20 11:42:46,174 [INFO]  Found 19 metrics for ns_id:1a/vnf_member_index:1
2019-06-20 11:42:46,175 [INFO]  Using Arima for prediction
2019-06-20 11:42:46,175 [INFO]  Start predicting with Arima
2019-06-20 11:42:46,175 [INFO]  Will train with 19 values
2019-06-20 11:42:46,177 [ERROR]  Singular matrix detected.All metric values must be the same.Adding noise to overcome
Traceback (most recent call last):
  File "/Users/ioanniskalyvas/PycharmProjects/5ginfire/prediction/predictor/predictors/predictor_utils.py", line 156, in predict
    model_fit = model.fit(disp=False)
  File "/Users/ioanniskalyvas/PycharmProjects/5ginfire/prediction/venv/lib/python3.7/site-packages/statsmodels/tsa/arima_model.py", line 1157, in fit
    callback, start_ar_lags, **kwargs)
  File "/Users/ioanniskalyvas/PycharmProjects/5ginfire/prediction/venv/lib/python3.7/site-packages/statsmodels/tsa/arima_model.py", line 946, in fit
    start_ar_lags)
  File "/Users/ioanniskalyvas/PycharmProjects/5ginfire/prediction/venv/lib/python3.7/site-packages/statsmodels/tsa/arima_model.py", line 562, in _fit_start_params
    start_params = self._fit_start_params_hr(order, start_ar_lags)
  File "/Users/ioanniskalyvas/PycharmProjects/5ginfire/prediction/venv/lib/python3.7/site-packages/statsmodels/tsa/arima_model.py", line 535, in _fit_start_params_hr
    arcoefs = yule_walker(endog, order=p)[0]
  File "/Users/ioanniskalyvas/PycharmProjects/5ginfire/prediction/venv/lib/python3.7/site-packages/statsmodels/regression/linear_model.py", line 1278, in yule_walker
    rho = np.linalg.solve(R, r[1:])
  File "/Users/ioanniskalyvas/PycharmProjects/5ginfire/prediction/venv/lib/python3.7/site-packages/numpy/linalg/linalg.py", line 403, in solve
    r = gufunc(a, b, signature=signature, extobj=extobj)
  File "/Users/ioanniskalyvas/PycharmProjects/5ginfire/prediction/venv/lib/python3.7/site-packages/numpy/linalg/linalg.py", line 97, in _raise_linalgerror_singular
    raise LinAlgError("Singular matrix")
numpy.linalg.LinAlgError: Singular matrix
2019-06-20 11:42:46,264 [INFO]  Predict that the next value will be 1.453520928422346
2019-06-20 11:42:46,264 [INFO]  Predicted cpu load is 1.453520928422346.Need 1 for this cpu load.
2019-06-20 11:42:48,246 [INFO]  Got token MBccVqSE65I5CsLPdqAzeN8hdS9U9bSf
2019-06-20 11:42:48,247 [WARNING]  Scale in operation triggered.Will scale by 2
2019-06-20 11:42:50,026 [ERROR]  Could not send SCALE_IN to LCM.422/{
    "status": 422,
    "code": "UNPROCESSABLE_ENTITY",
    "detail": "Format error at 'nsInstanceId' ''1a' does not match '^[a-fA-F0-9]{8}(-[a-fA-F0-9]{4}){3}-[a-fA-F0-9]{12}$'' "
}

2019-06-20 11:42:55,069 [ERROR]  Could not send SCALE_IN to LCM.422/{
    "status": 422,
    "code": "UNPROCESSABLE_ENTITY",
    "detail": "Format error at 'nsInstanceId' ''1a' does not match '^[a-fA-F0-9]{8}(-[a-fA-F0-9]{4}){3}-[a-fA-F0-9]{12}$'' "
}

2019-06-20 15:03:06,922 [INFO]  Found 20 metrics for ns_id:1a/vnf_member_index:1
2019-06-20 15:03:06,923 [INFO]  Using Arima for prediction
2019-06-20 15:03:06,923 [INFO]  Start predicting with Arima
2019-06-20 15:03:06,924 [INFO]  Will train with 20 values
2019-06-20 15:03:06,925 [ERROR]  Singular matrix detected.All metric values must be the same.Adding noise to overcome
Traceback (most recent call last):
  File "/Users/ioanniskalyvas/PycharmProjects/5ginfire/prediction/predictor/predictors/predictor_utils.py", line 162, in predict
    model_fit = model.fit(disp=False)
  File "/Users/ioanniskalyvas/PycharmProjects/5ginfire/prediction/venv/lib/python3.7/site-packages/statsmodels/tsa/arima_model.py", line 1158, in fit
    callback, start_ar_lags, **kwargs)
  File "/Users/ioanniskalyvas/PycharmProjects/5ginfire/prediction/venv/lib/python3.7/site-packages/statsmodels/tsa/arima_model.py", line 947, in fit
    start_ar_lags)
  File "/Users/ioanniskalyvas/PycharmProjects/5ginfire/prediction/venv/lib/python3.7/site-packages/statsmodels/tsa/arima_model.py", line 563, in _fit_start_params
    start_params = self._fit_start_params_hr(order, start_ar_lags)
  File "/Users/ioanniskalyvas/PycharmProjects/5ginfire/prediction/venv/lib/python3.7/site-packages/statsmodels/tsa/arima_model.py", line 536, in _fit_start_params_hr
    arcoefs = yule_walker(endog, order=p)[0]
  File "/Users/ioanniskalyvas/PycharmProjects/5ginfire/prediction/venv/lib/python3.7/site-packages/statsmodels/regression/linear_model.py", line 1278, in yule_walker
    rho = np.linalg.solve(R, r[1:])
  File "/Users/ioanniskalyvas/PycharmProjects/5ginfire/prediction/venv/lib/python3.7/site-packages/numpy/linalg/linalg.py", line 403, in solve
    r = gufunc(a, b, signature=signature, extobj=extobj)
  File "/Users/ioanniskalyvas/PycharmProjects/5ginfire/prediction/venv/lib/python3.7/site-packages/numpy/linalg/linalg.py", line 97, in _raise_linalgerror_singular
    raise LinAlgError("Singular matrix")
numpy.linalg.LinAlgError: Singular matrix
2019-06-20 15:03:07,007 [INFO]  Predict that the next value will be 1.453521537117987
2019-06-20 15:03:07,007 [INFO]  Predicted cpu load is 1.453521537117987.Need 1 for this cpu load.
2019-06-20 15:03:07,452 [INFO]  Got token 9aNa0vNDcBZk9GRBR9yIIHzAyUNjbqAw
2019-06-20 15:03:07,453 [WARNING]  Scale in operation triggered.Will scale by 2
2019-06-20 15:03:07,964 [ERROR]  Could not send SCALE_IN to LCM.422/{
    "status": 422,
    "code": "UNPROCESSABLE_ENTITY",
    "detail": "Format error at 'nsInstanceId' ''1a' does not match '^[a-fA-F0-9]{8}(-[a-fA-F0-9]{4}){3}-[a-fA-F0-9]{12}$'' "
}

2019-06-20 15:03:11,396 [ERROR]  Could not send SCALE_IN to LCM.422/{
    "status": 422,
    "code": "UNPROCESSABLE_ENTITY",
    "detail": "Format error at 'nsInstanceId' ''1a' does not match '^[a-fA-F0-9]{8}(-[a-fA-F0-9]{4}){3}-[a-fA-F0-9]{12}$'' "
}

2019-06-20 15:05:35,292 [INFO]  /Users/ioanniskalyvas/PycharmProjects/5ginfire/prediction/predictor/predictors/predictor_utils.py changed, reloading.
